Workbook

Sheet FULL
A1: № | B1: MFO | C1: BXM | D1: Joylashgan joyi | E1: Bankomat turi | F1: Bankomat modeli | G1: Holati | H1: Servis | I1: Servis to‘lovi | J1: Seriya raqami | K1: Inventar raqami | L1: Yuridik manzili | M1: Merchant ID | N1: Terminal ID | O1: 2026 Yanvar | P1: 2026 Fevral | Q1: 2026 Mart | R1: 2026 Aprel | S1: 2026 May | T1: 2026 Iyun | U1: 2026 Iyul | V1: 2026 avgust | W1: 2026 sentabr | X1: 2026 oktabr | Y1: 2026 noyabr | Z1: 2026 dekabr | AA1: Jami | AB1: 23510 | AC1: 45265 | AD1: Sotib olingan sana | AE1: Sotib olingan qiymat
A2: 1 | B2: 11278 | C2: Buxoro | D2: BXM 24/7 | E2: Uzcard | F2: NCR6622 | G2: Soz | J2: 13-55551694 | K2: 00111-1718 | L2: Buxoro shahar Ibrohim Mo'minov ko'chasi 29/1 uy | M2: 901115126 | N2: 15897 | O2: =VLOOKUP(N2,Uzcard!C:P,4,0) -> 8094.65 | P2: =VLOOKUP(N2,Uzcard!C:P,6,0) -> 6413.9 | Q2: =VLOOKUP(N2,Uzcard!C:P,8,0) -> 10669.95 | R2: =VLOOKUP(N2,Uzcard!C:P,10,0) -> 7487.35 | S2: =VLOOKUP(N2,Uzcard!C:P,12,0) -> 12007.15 | T2: =VLOOKUP(N2,Uzcard!C:P,14,0) -> 8432.75 | U2: =IFERROR(VLOOKUP(N2,'2026 iyul uzcard'!A:D,3,0),"0")/1000 -> 6616.4 | AA2: =+SUM(O2:Z2) -> 59722.15 | AD2: 26.07.2018 | AE2: 1.0650721e+08
A3: 2 | B3: 11278 | C3: Buxoro | D3: BXM 24/7 | E3: Uzcard | F3: NCR6622 | G3: Nosoz | J3: 94-55605813 | K3: 00111-1828 | L3: Buxoro shahar Ibrohim Mo'minov ko'chasi 29/1 uy | M3: 901120490 | N3: 21411 | O3: =VLOOKUP(N3,Uzcard!C:P,4,0) -> 0 | P3: =VLOOKUP(N3,Uzcard!C:P,6,0) -> 0 | Q3: =VLOOKUP(N3,Uzcard!C:P,8,0) -> 0 | R3: =VLOOKUP(N3,Uzcard!C:P,10,0) -> 0 | S3: =VLOOKUP(N3,Uzcard!C:P,12,0) -> 0 | T3: =VLOOKUP(N3,Uzcard!C:P,14,0) -> 0 | U3: =IFERROR(VLOOKUP(N3,'2026 iyul uzcard'!A:D,3,0),"0")/1000 -> 0 | AA3: =+SUM(O3:Z3) -> 0 | AD3: 20.03.2019 | AE3: 1.0045819e+08
A4: 3 | B4: 11278 | C4: Buxoro | D4: BXM 24/7 | E4: Humo | F4: GRG | G4: Soz | H4: Glob | I4: 1848 | J4: 1108457422 | K4: 00111-3205 | L4: Buxoro shahar Ibrohim Mo'minov ko'chasi 29/1 uy | M4: 001110000011113 | N4: 157A0AK3 | O4: =VLOOKUP(N4,Humo!C:P,4,0) -> 7871.2 | P4: =VLOOKUP(N4,Humo!C:P,6,0) -> 7654 | Q4: =VLOOKUP(N4,Humo!C:P,8,0) -> 9045.1 | R4: =VLOOKUP(N4,Humo!C:P,10,0) -> 7816.1 | S4: =VLOOKUP(N4,Humo!C:P,12,0) -> 7770.9 | T4: =VLOOKUP(N4,Humo!C:P,14,0) -> 6855.7 | U4: =IFERROR(VLOOKUP(N4,'2026 iyul humo'!A:D,4,0),"0")/1000 -> 4233 | AA4: =+SUM(O4:Z4) -> 51246 | AD4: 12.02.2021 | AE4: 168243023
A5: 4 | B5: 11278 | C5: Buxoro | D5: BXM 24/7 | E5: Uzcard | F5: Hyusong | G5: Soz | H5: Btech | I5: 1128.7 | J5: YS45403483 | K5: 0000000110521 | L5: Buxoro shahar Ibrohim Mo'minov ko'chasi 29/1 uy | M5: 90110038049 | N5: 39945 | O5: =VLOOKUP(N5,Uzcard!C:P,4,0) -> 0 | P5: =VLOOKUP(N5,Uzcard!C:P,6,0) -> 0 | Q5: =VLOOKUP(N5,Uzcard!C:P,8,0) -> 0 | R5: =VLOOKUP(N5,Uzcard!C:P,10,0) -> 0 | S5: =VLOOKUP(N5,Uzcard!C:P,12,0) -> 0 | T5: =VLOOKUP(N5,Uzcard!C:P,14,0) -> 368 | U5: =IFERROR(VLOOKUP(N5,'2026 iyul uzcard'!A:D,3,0),"0")/1000 -> 3937.55 | AA5: =+SUM(O5:Z5) -> 4305.55 | AD5: 25.05.2026 | AE5: 362504800
A6: 5 | B6: 11278 | C6: Buxoro | D6: G'ijduvon tuman | E6: Uzcard | F6: NCR6623 | G6: Soz | H6: Btech | I6: 1128.7 | J6: 13-57828653 | K6: 00111-2649 | L6: G'ijduvon tuman Y.Hamadoniy ko'chasi 101 uy | M6: 901120485 | N6: 21378 | O6: =VLOOKUP(N6,Uzcard!C:P,4,0) -> 15166.55 | P6: =VLOOKUP(N6,Uzcard!C:P,6,0) -> 11555.45 | Q6: =VLOOKUP(N6,Uzcard!C:P,8,0) -> 23330.95 | R6: =VLOOKUP(N6,Uzcard!C:P,10,0) -> 14936.2 | S6: =VLOOKUP(N6,Uzcard!C:P,12,0) -> 20702.1 | T6: =VLOOKUP(N6,Uzcard!C:P,14,0) -> 19757.15 | U6: =IFERROR(VLOOKUP(N6,'2026 iyul uzcard'!A:D,3,0),"0")/1000 -> 10909.4 | AA6: =+SUM(O6:Z6) -> 116357.8 | AD6: 21.05.2020 | AE6: 131315497
A7: 6 | B7: 11278 | C7: Buxoro | D7: G'ijduvon tuman | E7: Humo | F7: NCR6623 | G7: Soz | H7: Glob | I7: 1848 | J7: 94-58406995 | K7: 00111-3402 | L7: G'ijduvon tuman Y.Hamadoniy ko'chasi 101 uy | M7: 00111000001111K | N7: 157A0C0U | O7: =VLOOKUP(N7,Humo!C:P,4,0) -> 3039.6 | P7: =VLOOKUP(N7,Humo!C:P,6,0) -> 7755.6 | Q7: =VLOOKUP(N7,Humo!C:P,8,0) -> 11574.2 | R7: =VLOOKUP(N7,Humo!C:P,10,0) -> 5240.3 | S7: =VLOOKUP(N7,Humo!C:P,12,0) -> 12583.5 | T7: =VLOOKUP(N7,Humo!C:P,14,0) -> 15923 | U7: =IFERROR(VLOOKUP(N7,'2026 iyul humo'!A:D,4,0),"0")/1000 -> 12575.4 | AA7: =+SUM(O7:Z7) -> 68691.6 | AD7: 27.08.2021 | AE7: 105827950
A8: 7 | B8: 11278 | C8: Buxoro | D8: G'ijduvon tuman | E8: Humo | F8: NCR6623 | G8: Soz | H8: Glob | I8: 1848 | J8: 94-58406990 | K8: 00446/492816-2 | L8: G'ijduvon tuman Degrezon ko'chasi | M8: 00111000004461U | N8: 1570000E | O8: =VLOOKUP(N8,Humo!C:P,4,0) -> 8943.3 | P8: =VLOOKUP(N8,Humo!C:P,6,0) -> 6374.4 | Q8: =VLOOKUP(N8,Humo!C:P,8,0) -> 10319.1 | R8: =VLOOKUP(N8,Humo!C:P,10,0) -> 5161.6 | S8: =VLOOKUP(N8,Humo!C:P,12,0) -> 1333 | T8: =VLOOKUP(N8,Humo!C:P,14,0) -> 8969.6 | U8: =IFERROR(VLOOKUP(N8,'2026 iyul humo'!A:D,4,0),"0")/1000 -> 8537.35 | AA8: =+SUM(O8:Z8) -> 49638.35 | AD8: 11.08.2021 | AE8: 105827950
A9: 8 | B9: 11278 | C9: Buxoro | D9: G'ijduvon tuman | E9: Humo | F9: Diebold | G9: Soz | H9: Glob | I9: 1848 | J9: 5310177380 | K9: 00111-1947 | L9: G'ijduvon tuman Degrezon ko'chasi | M9: 001110000044620 | N9: 1570001V | O9: =VLOOKUP(N9,Humo!C:P,4,0) -> 0 | P9: =VLOOKUP(N9,Humo!C:P,6,0) -> 0 | Q9: =VLOOKUP(N9,Humo!C:P,8,0) -> 0 | R9: =VLOOKUP(N9,Humo!C:P,10,0) -> 0 | S9: =VLOOKUP(N9,Humo!C:P,12,0) -> 0 | T9: =VLOOKUP(N9,Humo!C:P,14,0) -> 1188.5 | U9: =IFERROR(VLOOKUP(N9,'2026 iyul humo'!A:D,4,0),"0")/1000 -> 2915.05 | AA9: =+SUM(O9:Z9) -> 4103.55 | AD9: 23.12.2019 | AE9: 62805331
A10: 9 | B10: 11278 | C10: Buxoro | D10: Kogon BXO | E10: Uzcard | F10: NCR6623 | G10: Soz | H10: Btech | I10: 1128.7 | J10: 13-57828718 | K10: 00111-2650 | L10: Kogon shahar Buxoroshox ko'chasi 23 A uy | M10: 901120416 | N10: 21302 | O10: =VLOOKUP(N10,Uzcard!C:P,4,0) -> 5307.05 | P10: =VLOOKUP(N10,Uzcard!C:P,6,0) -> 13533.35 | Q10: =VLOOKUP(N10,Uzcard!C:P,8,0) -> 9512.45 | R10: =VLOOKUP(N10,Uzcard!C:P,10,0) -> 10363.25 | S10: =VLOOKUP(N10,Uzcard!C:P,12,0) -> 13863.75 | T10: =VLOOKUP(N10,Uzcard!C:P,14,0) -> 13463.25 | U10: =IFERROR(VLOOKUP(N10,'2026 iyul uzcard'!A:D,3,0),"0")/1000 -> 13053.9 | AA10: =+SUM(O10:Z10) -> 79097 | AD10: 21.05.2020 | AE10: 131315497
A11: 10 | B11: 11278 | C11: Buxoro | D11: Kogon BXO | E11: Humo | F11: Diebold | G11: Soz | H11: Glob | I11: 1848 | J11: 5310177914 | K11: 00111-2034 | L11: Kogon shahar Buxoroshox ko'chasi 23 A uy | M11: 00111000001110С | N11: 157A062W | O11: =VLOOKUP(N11,Humo!C:P,4,0) -> 4161.9 | P11: =VLOOKUP(N11,Humo!C:P,6,0) -> 1753.7 | Q11: =VLOOKUP(N11,Humo!C:P,8,0) -> 9448.4 | R11: =VLOOKUP(N11,Humo!C:P,10,0) -> 5956.7 | S11: =VLOOKUP(N11,Humo!C:P,12,0) -> 7364.9 | T11: =VLOOKUP(N11,Humo!C:P,14,0) -> 7388.8 | U11: =IFERROR(VLOOKUP(N11,'2026 iyul humo'!A:D,4,0),"0")/1000 -> 4481.05 | AA11: =+SUM(O11:Z11) -> 40555.45 | AD11: 30.12.2019 | AE11: 62805331
A12: 11 | B12: 11278 | C12: Buxoro | D12: Qorako'l BXO | E12: Uzcard | F12: NCR6623 | G12: Soz | H12: Btech | I12: 1128.7 | J12: 13-57828663 | K12: 00111-2651 | L12: Qorako'l tuman Ulug'bek ko'chasi | M12: 901120491 | N12: 22691 | O12: =VLOOKUP(N12,Uzcard!C:P,4,0) -> 11883.95 | P12: =VLOOKUP(N12,Uzcard!C:P,6,0) -> 5415.95 | Q12: =VLOOKUP(N12,Uzcard!C:P,8,0) -> 5479.65 | R12: =VLOOKUP(N12,Uzcard!C:P,10,0) -> 9428 | S12: =VLOOKUP(N12,Uzcard!C:P,12,0) -> 16711.8 | T12: =VLOOKUP(N12,Uzcard!C:P,14,0) -> 13744.4 | U12: =IFERROR(VLOOKUP(N12,'2026 iyul uzcard'!A:D,3,0),"0")/1000 -> 4932.3 | AA12: =+SUM(O12:Z12) -> 67596.05 | AD12: 21.05.2020 | AE12: 131315497
A13: 12 | B13: 11278 | C13: Buxoro | D13: Qorako'l BXO | E13: Humo | F13: Diebold | G13: Soz | H13: Glob | I13: 1848 | J13: 5310178092 | K13: 2020-8 | L13: Qorako'l tuman Ulug'bek ko'chasi | M13: 00111000001111E | N13: 157A0B8L | O13: =VLOOKUP(N13,Humo!C:P,4,0) -> 3257.8 | P13: =VLOOKUP(N13,Humo!C:P,6,0) -> 4775.4 | Q13: =VLOOKUP(N13,Humo!C:P,8,0) -> 8800.5 | R13: =VLOOKUP(N13,Humo!C:P,10,0) -> 0 | S13: =VLOOKUP(N13,Humo!C:P,12,0) -> 0 | T13: =VLOOKUP(N13,Humo!C:P,14,0) -> 3905.6 | U13: =IFERROR(VLOOKUP(N13,'2026 iyul humo'!A:D,4,0),"0")/1000 -> 4229.15 | AA13: =+SUM(O13:Z13) -> 24968.45 | AD13: 25.05.2020 | AE13: 62805331
A14: 13 | B14: 11278 | C14: Buxoro | D14: Eski shahar | E14: Uzcard | F14: NCR6623 | G14: Soz | H14: Btech | I14: 1128.7 | J14: 13-59981127 | K14: 00111-3400 | L14: Buxoro shahar Haqiqat ko'chasi 9 uy | M14: 901124759 | N14: 25781 | O14: =VLOOKUP(N14,Uzcard!C:P,4,0) -> 598.2 | P14: =VLOOKUP(N14,Uzcard!C:P,6,0) -> 1606.45 | Q14: =VLOOKUP(N14,Uzcard!C:P,8,0) -> 5281.85 | R14: =VLOOKUP(N14,Uzcard!C:P,10,0) -> 9270.85 | S14: =VLOOKUP(N14,Uzcard!C:P,12,0) -> 9646.05 | T14: =VLOOKUP(N14,Uzcard!C:P,14,0) -> 4789.35 | U14: =IFERROR(VLOOKUP(N14,'2026 iyul uzcard'!A:D,3,0),"0")/1000 -> 3606.75 | AA14: =+SUM(O14:Z14) -> 34799.5 | AD14: 27.08.2021 | AE14: 144808312
A15: 14 | B15: 11278 | C15: Buxoro | D15: Guliver | E15: Uzcard | F15: NCR6622 | G15: Soz | J15: 94-55605803 | K15: 00111-1829 | L15: Buxoro shahar Piridastgir ko'chasi 5 A uy | M15: 901117504 | N15: 18327 | O15: =VLOOKUP(N15,Uzcard!C:P,4,0) -> 7029.55 | P15: =VLOOKUP(N15,Uzcard!C:P,6,0) -> 4062.75 | Q15: =VLOOKUP(N15,Uzcard!C:P,8,0) -> 8155.2 | R15: =VLOOKUP(N15,Uzcard!C:P,10,0) -> 4131.2 | S15: =VLOOKUP(N15,Uzcard!C:P,12,0) -> 11999.6 | T15: =VLOOKUP(N15,Uzcard!C:P,14,0) -> 11420.05 | U15: =IFERROR(VLOOKUP(N15,'2026 iyul uzcard'!A:D,3,0),"0")/1000 -> 9304.3 | AA15: =+SUM(O15:Z15) -> 56102.65 | AD15: 20.03.2019 | AE15: 1.0045819e+08
A16: 15 | B16: 11278 | C16: Buxoro | D16: Guliver | E16: Humo | F16: NCR6623 | G16: Soz | H16: Glob | I16: 1848 | J16: 94-58406997 | K16: 00111-3401 | L16: Buxoro shahar S Murodov ko'chasi | M16: 00111000001111L | N16: 157A0C0V | O16: =VLOOKUP(N16,Humo!C:P,4,0) -> 1923.7 | P16: =VLOOKUP(N16,Humo!C:P,6,0) -> 2416.6 | Q16: =VLOOKUP(N16,Humo!C:P,8,0) -> 3752.7 | R16: =VLOOKUP(N16,Humo!C:P,10,0) -> 3321.7 | S16: =VLOOKUP(N16,Humo!C:P,12,0) -> 3826 | T16: =VLOOKUP(N16,Humo!C:P,14,0) -> 0 | U16: =IFERROR(VLOOKUP(N16,'2026 iyul humo'!A:D,4,0),"0")/1000 -> 0 | AA16: =+SUM(O16:Z16) -> 15240.7 | AD16: 27.08.2021 | AE16: 105827950
A17: 16 | B17: 11278 | C17: Buxoro | D17: Zarmanoq | E17: Humo | F17: Diebold | G17: Soz | H17: Glob | I17: 1848 | J17: 5310177340 | K17: 00111-3330 | L17: Buxoro tuman Zarmanoq mfy | M17: 00111000001111F | N17: 157A0B8M | O17: =VLOOKUP(N17,Humo!C:P,4,0) -> 3087.4 | P17: =VLOOKUP(N17,Humo!C:P,6,0) -> 2820.6 | Q17: =VLOOKUP(N17,Humo!C:P,8,0) -> 3433.4 | R17: =VLOOKUP(N17,Humo!C:P,10,0) -> 2753.9 | S17: =VLOOKUP(N17,Humo!C:P,12,0) -> 3378.3 | T17: =VLOOKUP(N17,Humo!C:P,14,0) -> 2326.8 | U17: =IFERROR(VLOOKUP(N17,'2026 iyul humo'!A:D,4,0),"0")/1000 -> 3302.1 | AA17: =+SUM(O17:Z17) -> 21102.5 | AD17: 20.12.2019 | AE17: 62805331
A18: 17 | B18: 11278 | C18: Buxoro | D18: Omborda | E18: Uzcard | F18: NCR6622 | G18: Nosoz | J18: 94-55605803 | K18: 00111-1827 | L18: Buxoro shahar Ibrohim Mo'minov ko'chasi 29/1 uy | M18: 901117296 | N18: 18114 | O18: =VLOOKUP(N18,Uzcard!C:P,4,0) -> 0 | P18: =VLOOKUP(N18,Uzcard!C:P,6,0) -> 0 | Q18: =VLOOKUP(N18,Uzcard!C:P,8,0) -> 0 | R18: =VLOOKUP(N18,Uzcard!C:P,10,0) -> 0 | S18: =VLOOKUP(N18,Uzcard!C:P,12,0) -> 0 | T18: =VLOOKUP(N18,Uzcard!C:P,14,0) -> 0 | U18: =IFERROR(VLOOKUP(N18,'2026 iyul uzcard'!A:D,3,0),"0")/1000 -> 0 | AA18: =+SUM(O18:Z18) -> 0 | AD18: 20.03.2019 | AE18: 1.0045819e+08
A19: 18 | B19: 11278 | C19: Buxoro | D19: Omborda | E19: Humo | F19: Diebold | G19: Soz | H19: Glob | I19: 1848 | J19: 5310177323 | K19: 00111-1946 | L19: Buxoro shahar Ibrohim Mo'minov ko'chasi 29/1 uy | M19: 00111000001110A | N19: 157A05DK | O19: =VLOOKUP(N19,Humo!C:P,4,0) -> 0 | P19: =VLOOKUP(N19,Humo!C:P,6,0) -> 0 | Q19: =VLOOKUP(N19,Humo!C:P,8,0) -> 0 | R19: =VLOOKUP(N19,Humo!C:P,10,0) -> 0 | S19: =VLOOKUP(N19,Humo!C:P,12,0) -> 0 | T19: =VLOOKUP(N19,Humo!C:P,14,0) -> 0 | U19: =IFERROR(VLOOKUP(N19,'2026 iyul humo'!A:D,4,0),"0")/1000 -> 0 | AA19: =+SUM(O19:Z19) -> 0 | AD19: 23.12.2019 | AE19: 62805331
A20: 19 | B20: 11278 | C20: Buxoro | D20: Omborda | E20: Humo | F20: Diebold | G20: Nosoz | J20: 5310177420 | K20: 00111-1948 | L20: Buxoro shahar Ibrohim Mo'minov ko'chasi 29/1 uy | M20: 001110000011109 | N20: 157A05DJ | O20: =VLOOKUP(N20,Humo!C:P,4,0) -> 0 | P20: =VLOOKUP(N20,Humo!C:P,6,0) -> 0 | Q20: =VLOOKUP(N20,Humo!C:P,8,0) -> 0 | R20: =VLOOKUP(N20,Humo!C:P,10,0) -> 0 | S20: =VLOOKUP(N20,Humo!C:P,12,0) -> 0 | T20: =VLOOKUP(N20,Humo!C:P,14,0) -> 0 | U20: =IFERROR(VLOOKUP(N20,'2026 iyul humo'!A:D,4,0),"0")/1000 -> 0 | AA20: =+SUM(O20:Z20) -> 0 | AD20: 23.12.2019 | AE20: 62805331
A21: 20 | B21: 11278 | C21: Buxoro | D21: Omborda | E21: Vash | F21: Tactilion | G21: Nosoz | J21: 218258 | K21: 00111-1737 | L21: Buxoro shahar Haqiqat ko'chasi 9 uy | M21: TBATM010 | N21: TBATM010 | O21: =IFERROR(VLOOKUP(N21,'2026 yanvar vash'!A:D,4,0),"0")/1000 -> 0 | P21: =IFERROR(VLOOKUP(N21,'2026 fevral vash'!A:D,4,0),"0")/1000 -> 0 | Q21: =IFERROR(VLOOKUP(N21,'2026 mart vash'!A:D,4,0),"0")/1000 -> 0 | R21: =IFERROR(VLOOKUP(N21,'2026 aprel vash'!A:D,4,0),"0")/1000 -> 0 | S21: =IFERROR(VLOOKUP(N21,'2026 may vash'!A:D,4,0),"0")/1000 -> 0 | T21: =IFERROR(VLOOKUP(N21,'2026 iyun vash'!A:D,4,0),"0")/1000 -> 0 | U21: =IFERROR(VLOOKUP(N21,'2026 iyul vash'!A:D,4,0),"0")/1000 -> 0 | AA21: =+SUM(O21:Z21) -> 0 | AD21: 03.11.2018 | AE21: 1.7190484e+08
A22: 21 | B22: 11278 | C22: Buxoro | D22: Omborda | E22: Vash | F22: Tactilion | G22: Nosoz | J22: 318258 | K22: 00111-1738 | L22: Buxoro shahar Ibrohim Mo'minov ko'chasi 29/1 uy | M22: TBATM009 | N22: TBATM009 | O22: =IFERROR(VLOOKUP(N22,'2026 yanvar vash'!A:D,4,0),"0")/1000 -> 214.1 | P22: =IFERROR(VLOOKUP(N22,'2026 fevral vash'!A:D,4,0),"0")/1000 -> 221.43 | Q22: =IFERROR(VLOOKUP(N22,'2026 mart vash'!A:D,4,0),"0")/1000 -> 396.71 | R22: =IFERROR(VLOOKUP(N22,'2026 aprel vash'!A:D,4,0),"0")/1000 -> 129.4 | S22: =IFERROR(VLOOKUP(N22,'2026 may vash'!A:D,4,0),"0")/1000 -> 0 | T22: =IFERROR(VLOOKUP(N22,'2026 iyun vash'!A:D,4,0),"0")/1000 -> 0 | U22: =IFERROR(VLOOKUP(N22,'2026 iyul vash'!A:D,4,0),"0")/1000 -> 0 | AA22: =+SUM(O22:Z22) -> 961.64 | AD22: 03.11.2018 | AE22: 1.7190484e+08
A23: 22 | B23: 11279 | C23: Qarshi | D23: BXM 24/7 | E23: Uzcard | F23: NCR6623 | G23: Soz | H23: Btech | I23: 1128.7 | J23: 13-57828669 | K23: 00192/1801/49 | L23: Qarshi shahar Komilon ko'chasi 28-A uy | M23: 901120268 | N23: 21147 | O23: =VLOOKUP(N23,Uzcard!C:P,4,0) -> 8328.15 | P23: =VLOOKUP(N23,Uzcard!C:P,6,0) -> 9282.4 | Q23: =VLOOKUP(N23,Uzcard!C:P,8,0) -> 12993.5 | R23: =VLOOKUP(N23,Uzcard!C:P,10,0) -> 8168.7 | S23: =VLOOKUP(N23,Uzcard!C:P,12,0) -> 13880.2 | T23: =VLOOKUP(N23,Uzcard!C:P,14,0) -> 13885.55 | U23: =IFERROR(VLOOKUP(N23,'2026 iyul uzcard'!A:D,3,0),"0")/1000 -> 7930.65 | AA23: =+SUM(O23:Z23) -> 74469.15 | AD23: 23.08.2021 | AE23: 105827950
A24: 23 | B24: 11279 | C24: Qarshi | D24: BXM 24/7 | E24: Humo | F24: Diebold | G24: Soz | H24: Glob | I24: 1848 | J24: 5310177426 | K24: 00192/2005 | L24: Qarshi shahar Komilon ko'chasi 28-A uy | M24: 1920000019202 | N24: 157A05AT | O24: =VLOOKUP(N24,Humo!C:P,4,0) -> 7537.35 | P24: =VLOOKUP(N24,Humo!C:P,6,0) -> 4656.95 | Q24: =VLOOKUP(N24,Humo!C:P,8,0) -> 11734.75 | R24: =VLOOKUP(N24,Humo!C:P,10,0) -> 7659.5 | S24: =VLOOKUP(N24,Humo!C:P,12,0) -> 5598.8 | T24: =VLOOKUP(N24,Humo!C:P,14,0) -> 9881.8 | U24: =IFERROR(VLOOKUP(N24,'2026 iyul humo'!A:D,4,0),"0")/1000 -> 4313.85 | AA24: =+SUM(O24:Z24) -> 51383 | AD24: 27.12.2019 | AE24: 62805331
A25: 24 | B25: 11279 | C25: Qarshi | D25: BXM 24/7 | E25: Humo | F25: GRG | G25: Soz | H25: Glob | I25: 1848 | J25: 1108457423 | K25: 00192/1658 | L25: Qarshi shahar Komilon ko'chasi 28-A uy | M25: 00192000001920T | N25: 157A0AKF | O25: =VLOOKUP(N25,Humo!C:P,4,0) -> 2072.8 | P25: =VLOOKUP(N25,Humo!C:P,6,0) -> 443.3 | Q25: =VLOOKUP(N25,Humo!C:P,8,0) -> 65.3 | R25: =VLOOKUP(N25,Humo!C:P,10,0) -> 4 | S25: =VLOOKUP(N25,Humo!C:P,12,0) -> 2.8 | T25: =VLOOKUP(N25,Humo!C:P,14,0) -> 1011.1 | U25: =IFERROR(VLOOKUP(N25,'2026 iyul humo'!A:D,4,0),"0")/1000 -> 2940.55 | AA25: =+SUM(O25:Z25) -> 6539.85 | AD25: 18.03.2021 | AE25: 168243023
A26: 25 | B26: 11279 | C26: Qarshi | D26: BXM 24/7 | E26: Vash | F26: Tactilion | G26: Nosoz | J26: 518258 | K26: 00192/1803/1 | L26: Qarshi shahar Komilon ko'chasi 28-A uy | M26: TBATM011 | N26: TBATM011 | O26: =IFERROR(VLOOKUP(N26,'2026 yanvar vash'!A:D,4,0),"0")/1000 -> 77 | P26: =IFERROR(VLOOKUP(N26,'2026 fevral vash'!A:D,4,0),"0")/1000 -> 200.31 | Q26: =IFERROR(VLOOKUP(N26,'2026 mart vash'!A:D,4,0),"0")/1000 -> 53.35 | R26: =IFERROR(VLOOKUP(N26,'2026 aprel vash'!A:D,4,0),"0")/1000 -> 37.75 | S26: =IFERROR(VLOOKUP(N26,'2026 may vash'!A:D,4,0),"0")/1000 -> 44.65 | T26: =IFERROR(VLOOKUP(N26,'2026 iyun vash'!A:D,4,0),"0")/1000 -> 71.7 | U26: =IFERROR(VLOOKUP(N26,'2026 iyul vash'!A:D,4,0),"0")/1000 -> 10.2 | AA26: =+SUM(O26:Z26) -> 494.96 | AD26: 29.12.2018 | AE26: 1.7190484e+08
A27: 26 | B27: 11279 | C27: Qarshi | D27: BXM 24/7 | E27: Uzcard | F27: Hyusong | G27: Soz | H27: Btech | I27: 1128.7 | J27: YS45403348 | K27: 0000000110561 | L27: Qarshi shahar Komilon ko'chasi 28-A uy | M27: 90110038101 | N27: 39996 | O27: =VLOOKUP(N27,Uzcard!C:P,4,0) -> 0 | P27: =VLOOKUP(N27,Uzcard!C:P,6,0) -> 0 | Q27: =VLOOKUP(N27,Uzcard!C:P,8,0) -> 0 | R27: =VLOOKUP(N27,Uzcard!C:P,10,0) -> 0 | S27: =VLOOKUP(N27,Uzcard!C:P,12,0) -> 0 | T27: =VLOOKUP(N27,Uzcard!C:P,14,0) -> 98.9 | U27: =IFERROR(VLOOKUP(N27,'2026 iyul uzcard'!A:D,3,0),"0")/1000 -> 8298.7 | AA27: =+SUM(O27:Z27) -> 8397.6 | AD27: 25.05.2026 | AE27: 362504800
A28: 27 | B28: 11279 | C28: Qarshi | D28: Mirishkor BXO | E28: Humo | F28: Diebold | G28: Soz | H28: Glob | I28: 1848 | J28: 5310177307 | K28: 00192/2006 | L28: Mirishkor tumani А.Temur ko'chasi 6-uy | M28: 1920000019203 | N28: 157A05AU | O28: =VLOOKUP(N28,Humo!C:P,4,0) -> 6531.9 | P28: =VLOOKUP(N28,Humo!C:P,6,0) -> 5552.9 | Q28: =VLOOKUP(N28,Humo!C:P,8,0) -> 4773.6 | R28: =VLOOKUP(N28,Humo!C:P,10,0) -> 2988.8 | S28: =VLOOKUP(N28,Humo!C:P,12,0) -> 5269.2 | T28: =VLOOKUP(N28,Humo!C:P,14,0) -> 6496.1 | U28: =IFERROR(VLOOKUP(N28,'2026 iyul humo'!A:D,4,0),"0")/1000 -> 5795.15 | AA28: =+SUM(O28:Z28) -> 37407.65 | AD28: 27.12.2019 | AE28: 62805331
A29: 28 | B29: 11279 | C29: Qarshi | D29: Mirishkor BXO | E29: Uzcard | F29: NCR6623 | G29: Soz | H29: Btech | I29: 1128.7 | J29: 13-57828652 | K29: 00192/1803 | L29: Mirishkor tumani А.Temur ko'chasi 6-uy | M29: 901120269 | N29: 21148 | O29: =VLOOKUP(N29,Uzcard!C:P,4,0) -> 10431.25 | P29: =VLOOKUP(N29,Uzcard!C:P,6,0) -> 3957.8 | Q29: =VLOOKUP(N29,Uzcard!C:P,8,0) -> 9524.45 | R29: =VLOOKUP(N29,Uzcard!C:P,10,0) -> 5606.7 | S29: =VLOOKUP(N29,Uzcard!C:P,12,0) -> 7576.95 | T29: =VLOOKUP(N29,Uzcard!C:P,14,0) -> 12446.85 | U29: =IFERROR(VLOOKUP(N29,'2026 iyul uzcard'!A:D,3,0),"0")/1000 -> 7735.95 | AA29: =+SUM(O29:Z29) -> 57279.95 | AD29: 23.08.2021 | AE29: 105827950
A30: 29 | B30: 11279 | C30: Qarshi | D30: Kompleks market BXO | E30: Uzcard | F30: NCR6623 | G30: Soz | H30: Btech | I30: 1128.7 | J30: 13-57828679 | K30: 00192/1800/1 | L30: Qarshi shahar Islom karimov ko'chasi 13-uy | M30: 901120413 | N30: 21299 | O30: =VLOOKUP(N30,Uzcard!C:P,4,0) -> 3312.45 | P30: =VLOOKUP(N30,Uzcard!C:P,6,0) -> 860.5 | Q30: =VLOOKUP(N30,Uzcard!C:P,8,0) -> 6031.6 | R30: =VLOOKUP(N30,Uzcard!C:P,10,0) -> 4090.6 | S30: =VLOOKUP(N30,Uzcard!C:P,12,0) -> 2636.25 | T30: =VLOOKUP(N30,Uzcard!C:P,14,0) -> 5893.85 | U30: =IFERROR(VLOOKUP(N30,'2026 iyul uzcard'!A:D,3,0),"0")/1000 -> 5587.85 | AA30: =+SUM(O30:Z30) -> 28413.1 | AD30: 23.08.2021 | AE30: 144808312
A31: 30 | B31: 11279 | C31: Qarshi | D31: Kompleks market BXO | E31: Uzcard | F31: NCR6622 | G31: Soz | J31: 13-54969410 | K31: 00192/1902_15959213 | L31: Qarshi shahar Islom karimov ko'chasi 13-uy | M31: 901119583 | N31: 20437 | O31: =VLOOKUP(N31,Uzcard!C:P,4,0) -> 111.9 | P31: =VLOOKUP(N31,Uzcard!C:P,6,0) -> 673.15 | Q31: =VLOOKUP(N31,Uzcard!C:P,8,0) -> 142 | R31: =VLOOKUP(N31,Uzcard!C:P,10,0) -> 76 | S31: =VLOOKUP(N31,Uzcard!C:P,12,0) -> 0 | T31: =VLOOKUP(N31,Uzcard!C:P,14,0) -> 0 | U31: =IFERROR(VLOOKUP(N31,'2026 iyul uzcard'!A:D,3,0),"0")/1000 -> 0 | AA31: =+SUM(O31:Z31) -> 1003.05 | AD31: 03.10.2019 | AE31: 1.0045819e+08
A32: 31 | B32: 11279 | C32: Qarshi | D32: Kompleks market BXO | E32: Humo | F32: Diebold | G32: Soz | H32: Glob | I32: 1848 | J32: 5310178048 | K32: 00192/2510 | L32: Qarshi shahar Islom karimov ko'chasi 13-uy | M32: 00192000001920A | N32: 157A05ZE | O32: =VLOOKUP(N32,Humo!C:P,4,0) -> 4673 | P32: =VLOOKUP(N32,Humo!C:P,6,0) -> 2775 | Q32: =VLOOKUP(N32,Humo!C:P,8,0) -> 59.8 | R32: =VLOOKUP(N32,Humo!C:P,10,0) -> 0 | S32: =VLOOKUP(N32,Humo!C:P,12,0) -> 2959.3 | T32: =VLOOKUP(N32,Humo!C:P,14,0) -> 6250 | U32: =IFERROR(VLOOKUP(N32,'2026 iyul humo'!A:D,4,0),"0")/1000 -> 4918.1 | AA32: =+SUM(O32:Z32) -> 21635.2 | AD32: 03.04.2020 | AE32: 63098416
A33: 32 | B33: 11279 | C33: Qarshi | D33: Farhod BXO | E33: Uzcard | F33: NCR6623 | G33: Soz | H33: Btech | I33: 1128.7 | J33: 13-59981121 | K33: 00192/1369/2 | L33: Qarshi shahar Farhod bozori | M33: 901124848 | N33: 25873 | O33: =VLOOKUP(N33,Uzcard!C:P,4,0) -> 6075.75 | P33: =VLOOKUP(N33,Uzcard!C:P,6,0) -> 5033.15 | Q33: =VLOOKUP(N33,Uzcard!C:P,8,0) -> 4296 | R33: =VLOOKUP(N33,Uzcard!C:P,10,0) -> 6955.25 | S33: =VLOOKUP(N33,Uzcard!C:P,12,0) -> 9526.4 | T33: =VLOOKUP(N33,Uzcard!C:P,14,0) -> 11652.1 | U33: =IFERROR(VLOOKUP(N33,'2026 iyul uzcard'!A:D,3,0),"0")/1000 -> 7859.75 | AA33: =+SUM(O33:Z33) -> 51398.4 | AD33: 14.07.2020 | AE33: 131315497
A34: 33 | B34: 11279 | C34: Qarshi | D34: Farhod BXO | E34: Humo | F34: NCR6623 | G34: Soz | H34: Glob | I34: 1848 | J34: 94-58406979 | K34: 00192/1370/1 | L34: Qarshi shahar Farhod bozori | M34: 001920000019210 | N34: 157A0C29 | O34: =VLOOKUP(N34,Humo!C:P,4,0) -> 1722.8 | P34: =VLOOKUP(N34,Humo!C:P,6,0) -> 2093.8 | Q34: =VLOOKUP(N34,Humo!C:P,8,0) -> 5989.6 | R34: =VLOOKUP(N34,Humo!C:P,10,0) -> 1329.7 | S34: =VLOOKUP(N34,Humo!C:P,12,0) -> 287.9 | T34: =VLOOKUP(N34,Humo!C:P,14,0) -> 2679.2 | U34: =IFERROR(VLOOKUP(N34,'2026 iyul humo'!A:D,4,0),"0")/1000 -> 2701.85 | AA34: =+SUM(O34:Z34) -> 16804.85 | AD34: 14.07.2020 | AE34: 131315497
A35: 34 | B35: 11279 | C35: Qarshi | D35: Koson | E35: Vash | F35: Tactilion | G35: Nosoz | J35: 219339 | K35: 00192/2511 | L35: Koson tumani Navbahor MFY Sh. Rashidov ko'chasi | M35: TBATM035 | N35: TBATM035 | O35: =IFERROR(VLOOKUP(N35,'2026 yanvar vash'!A:D,4,0),"0")/1000 -> 0.1 | P35: =IFERROR(VLOOKUP(N35,'2026 fevral vash'!A:D,4,0),"0")/1000 -> 0.01 | Q35: =IFERROR(VLOOKUP(N35,'2026 mart vash'!A:D,4,0),"0")/1000 -> 11.98 | R35: =IFERROR(VLOOKUP(N35,'2026 aprel vash'!A:D,4,0),"0")/1000 -> 13.95 | S35: =IFERROR(VLOOKUP(N35,'2026 may vash'!A:D,4,0),"0")/1000 -> 0 | T35: =IFERROR(VLOOKUP(N35,'2026 iyun vash'!A:D,4,0),"0")/1000 -> 0 | U35: =IFERROR(VLOOKUP(N35,'2026 iyul vash'!A:D,4,0),"0")/1000 -> 0 | AA35: =+SUM(O35:Z35) -> 26.04 | AD35: 03.04.2020 | AE35: 2.1655729e+08
A36: 35 | B36: 11279 | C36: Qarshi | D36: Koson | E36: Humo | F36: Diebold | G36: Soz | H36: Glob | I36: 1848 | J36: 5310181402 | K36: 00192/2513 | L36: Koson tumani Navbahor MFY Sh. Rashidov ko'chasi | M36: 00192000001920T | N36: 157A06XF | O36: =VLOOKUP(N36,Humo!C:P,4,0) -> 8689.6 | P36: =VLOOKUP(N36,Humo!C:P,6,0) -> 9488.4 | Q36: =VLOOKUP(N36,Humo!C:P,8,0) -> 10797.9 | R36: =VLOOKUP(N36,Humo!C:P,10,0) -> 6312.3 | S36: =VLOOKUP(N36,Humo!C:P,12,0) -> 11552.1 | T36: =VLOOKUP(N36,Humo!C:P,14,0) -> 10590.2 | U36: =IFERROR(VLOOKUP(N36,'2026 iyul humo'!A:D,4,0),"0")/1000 -> 6910.8 | AA36: =+SUM(O36:Z36) -> 64341.3 | AD36: 03.04.2020 | AE36: 62805331
A37: 36 | B37: 11279 | C37: Qarshi | D37: Javohir medical klinikasi | E37: Uzcard | F37: NCR6623 | G37: Soz | H37: Btech | I37: 1128.7 | J37: 13-57828650 | K37: 00192/1371 | L37: Qarshi shahar Xontepa MFY Burgut ko'chasi | M37: 901120414 | N37: 21300 | O37: =VLOOKUP(N37,Uzcard!C:P,4,0) -> 4411.8 | P37: =VLOOKUP(N37,Uzcard!C:P,6,0) -> 3688.9 | Q37: =VLOOKUP(N37,Uzcard!C:P,8,0) -> 5358.5 | R37: =VLOOKUP(N37,Uzcard!C:P,10,0) -> 5633.9 | S37: =VLOOKUP(N37,Uzcard!C:P,12,0) -> 6650.35 | T37: =VLOOKUP(N37,Uzcard!C:P,14,0) -> 7674.35 | U37: =IFERROR(VLOOKUP(N37,'2026 iyul uzcard'!A:D,3,0),"0")/1000 -> 3829.6 | AA37: =+SUM(O37:Z37) -> 37247.4 | AD37: 14.07.2020 | AE37: 131315497
A38: 37 | B38: 11279 | C38: Qarshi | D38: Omborda | E38: Uzcard | F38: NCR6622 | G38: Nosoz | J38: 13-55551783 | K38: 00192/1525/1 | L38: Qarshi shahar Komilon ko'chasi 28-A uy | M38: 901115134 | N38: 15903 | O38: =VLOOKUP(N38,Uzcard!C:P,4,0) -> 2623.625 | P38: =VLOOKUP(N38,Uzcard!C:P,6,0) -> 2456.6 | Q38: =VLOOKUP(N38,Uzcard!C:P,8,0) -> 26.5 | R38: =VLOOKUP(N38,Uzcard!C:P,10,0) -> 0 | S38: =VLOOKUP(N38,Uzcard!C:P,12,0) -> 0 | T38: =VLOOKUP(N38,Uzcard!C:P,14,0) -> 0 | U38: =IFERROR(VLOOKUP(N38,'2026 iyul uzcard'!A:D,3,0),"0")/1000 -> 0 | AA38: =+SUM(O38:Z38) -> 5106.725 | AD38: 28.08.2018 | AE38: 1.0650721e+08
A39: 38 | B39: 11279 | C39: Qarshi | D39: Omborda | E39: Uzcard | F39: NCR6622 | G39: Nosoz | J39: 94-55605796 | K39: 00192/1784/1 | L39: Qarshi shahri Nasaf ko'chasi Grand savdo do'koni oldida | M39: 901117251 | N39: 18057 | O39: =VLOOKUP(N39,Uzcard!C:P,4,0) -> 0.1 | P39: =VLOOKUP(N39,Uzcard!C:P,6,0) -> 0 | Q39: =VLOOKUP(N39,Uzcard!C:P,8,0) -> 0 | R39: =VLOOKUP(N39,Uzcard!C:P,10,0) -> 0 | S39: =VLOOKUP(N39,Uzcard!C:P,12,0) -> 0 | T39: =VLOOKUP(N39,Uzcard!C:P,14,0) -> 0 | U39: =IFERROR(VLOOKUP(N39,'2026 iyul uzcard'!A:D,3,0),"0")/1000 -> 0 | AA39: =+SUM(O39:Z39) -> 0.1 | AD39: 20.07.2018 | AE39: 1.0650721e+08
A40: 39 | B40: 11279 | C40: Qarshi | D40: Omborda | E40: Humo | F40: NCR6623 | G40: Nosoz | H40: Glob | I40: 1848 | J40: 94-58406999 | K40: 00192/1372 | L40: Qarshi shahri Nasaf ko'chasi Grand savdo do'koni oldida | M40: 001920000019211 | N40: 157A0C8M | O40: =VLOOKUP(N40,Humo!C:P,4,0) -> 1333.7 | P40: =VLOOKUP(N40,Humo!C:P,6,0) -> 2.3 | Q40: =VLOOKUP(N40,Humo!C:P,8,0) -> 244.6 | R40: =VLOOKUP(N40,Humo!C:P,10,0) -> 0 | S40: =VLOOKUP(N40,Humo!C:P,12,0) -> 0 | T40: =VLOOKUP(N40,Humo!C:P,14,0) -> 0 | U40: =IFERROR(VLOOKUP(N40,'2026 iyul humo'!A:D,4,0),"0")/1000 -> 0 | AA40: =+SUM(O40:Z40) -> 1580.6 | AD40: 14.07.2020 | AE40: 131315497
...

Sheet Uzcard
A1: БХМ номи | B1: Банкомат ўрнатилган манзил | C1: Terminal ID | D1: Bankomat modeli | E1: 2026 йил Январ Чиқим | F1: 2026 йил Январ Даромад | G1: 2026 йил Феврал Чиқим | H1: 2026 йил Феврал Даромад | I1: 2026 йил Март Чиқим | J1: 2026 йил Март Даромад | K1: 2026 йил Апрел Чиқим | L1: 2026 йил Апрел Даромад | M1: 2026 йил Май Чиқим | N1: 2026 йил Май Даромад | O1: 2026 йил Июнь Чиқим | P1: 2026 йил Июнь Даромад
A2: Бухоро | B2: Бухоро филиали биносида 24/7 | C2: 15897 | D2: NCR6622 | E2: 806566.56 | F2: 8094.65 | G2: 634117.49 | H2: 6413.9 | I2: 1058479.3 | J2: 10669.95 | K2: 747629.86 | L2: 7487.35 | M2: 1196735.1 | N2: 12007.15 | O2: 842024.32 | P2: 8432.75
A3: Бухоро | B3: Бухоро филиали биносида 24/7 | C3: 39945 | D3: Хюсонг | K3: 0 | L3: 0 | O3: 51156.732 | P3: 368
A4: Бухоро | B4: (Мохитабон БХО 24/7да эди) Омборда | C4: 18114 | D4: NCR6622 | E4: 0 | F4: 0 | G4: 0 | H4: 0 | I4: 0 | J4: 0 | K4: 0 | L4: 0 | M4: 0 | N4: 0 | O4: 0 | P4: 0
A5: Бухоро | B5: Piridastgir 5A uy 24/7 | C5: 18327 | D5: NCR6622 | E5: 705722.52 | F5: 7029.55 | G5: 405958.69 | H5: 4062.75 | I5: 817747.04 | J5: 8155.2 | K5: 408697.07 | L5: 4131.2 | M5: 1181567.6 | N5: 11999.6 | O5: 1126258.6 | P5: 11420.05
A6: Бухоро | B6: Когон БХО | C6: 21302 | D6: NCR6623 | E6: 529051.74 | F6: 5307.05 | G6: 1343159.8 | H6: 13533.35 | I6: 945522.94 | J6: 9512.45 | K6: 1038682.9 | L6: 10363.25 | M6: 1380309.9 | N6: 13863.75 | O6: 1343089.8 | P6: 13463.25
A7: Бухоро | B7: Қоракўл БХО | C7: 22691 | D7: NCR6623 | E7: 1191312.1 | F7: 11883.95 | G7: 542880.53 | H7: 5415.95 | I7: 541304.17 | J7: 5479.65 | K7: 941258.57 | L7: 9428 | M7: 1669575.1 | N7: 16711.8 | O7: 1374970.7 | P7: 13744.4
A8: Бухоро | B8: Ғиждувон БХО | C8: 21378 | D8: NCR6623 | E8: 1524491.4 | F8: 15166.55 | G8: 1143963.9 | H8: 11555.45 | I8: 2326287.6 | J8: 23330.95 | K8: 1491221.3 | L8: 14936.2 | M8: 2072221.4 | N8: 20702.1 | O8: 1978367.4 | P8: 19757.15
A9: Бухоро | B9: (Прибанк 24/7да эди) Омборда | C9: 21411 | D9: NCR6622 | E9: 0 | F9: 0 | G9: 0 | H9: 0 | I9: 0 | J9: 0 | K9: 0 | L9: 0 | M9: 0 | N9: 0 | O9: 0 | P9: 0
A10: Бухоро | B10: Эски шахар | C10: 25781 | D10: NCR6623 | E10: 52087.602 | F10: 598.2 | G10: 137964.84 | H10: 1606.45 | I10: 426416.57 | J10: 5281.85 | K10: 724241.58 | L10: 9270.85 | M10: 734356.4 | N10: 9646.05 | O10: 391714.56 | P10: 4789.35
A11: Қарши | B11: (Қарши филиал биносида 24/7 эди) Омборда | C11: 15903 | D11: NCR6622 | E11: 258116 | F11: 2623.625 | G11: 244549.14 | H11: 2456.6 | I11: 2676.4735 | J11: 26.5 | K11: 0 | L11: 0 | M11: 0 | N11: 0 | O11: 0 | P11: 0
A12: Қарши | B12: (Ирригация институти биносида эди) Омборда | C12: 18057 | D12: NCR6622 | E12: 10.0999 | F12: 0.1 | G12: 0 | H12: 0 | I12: 0 | J12: 0 | K12: 0 | L12: 0 | M12: 0 | N12: 0 | O12: 0 | P12: 0
A13: Қарши | B13: (Насаф БХОда эди) Омборда | C13: 20437 | D13: NCR6622 | E13: 11151.788 | F13: 111.9 | G13: 67412.477 | H13: 673.15 | I13: 14341.858 | J13: 142 | K13: 7675.924 | L13: 76 | M13: 0 | N13: 0 | O13: 0 | P13: 0
A14: Қарши | B14: Насаф БХО | C14: 21299 | D14: NCR6623 | E14: 326989.14 | F14: 3312.45 | G14: 80449.64 | H14: 860.5 | I14: 595495.57 | J14: 6031.6 | K14: 400016.51 | L14: 4090.6 | M14: 264633.61 | N14: 2636.25 | O14: 586017.96 | P14: 5893.85
A15: Қарши | B15: Косон БХО | C15: 21300 | D15: NCR6623 | E15: 435037.39 | F15: 4411.8 | G15: 366725.21 | H15: 3688.9 | I15: 535003.14 | J15: 5358.5 | K15: 564848.27 | L15: 5633.9 | M15: 665543.7 | N15: 6650.35 | O15: 760236.68 | P15: 7674.35
... A17: Қарши | B17: Прибанк 24/7 | C17: 21147 | D17: NCR6623 | E17: 829089.82 | F17: 8328.15 | G17: 921713.12 | H17: 9282.4 | I17: 1289250.5 | J17: 12993.5 | K17: 806440.53 | L17: 8168.7 | M17: 1370526.3 | N17: 13880.2 | O17: 1363521.7 | P17: 13885.55
A18: Қарши | B18: Прибанк 24/7 | C18: 39996 | D18: Хюсонг | K18: 0 | L18: 0 | O18: 10298.901 | P18: 98.9
A19: Қарши | B19: Фарход БХО | C19: 25873 | D19: NCR6623 | E19: 608959.67 | F19: 6075.75 | G19: 493048.12 | H19: 5033.15 | I19: 426861.7 | J19: 4296 | K19: 697438.29 | L19: 6955.25 | M19: 950736.87 | N19: 9526.4 | O19: 1158230.4 | P19: 11652.1
A20: Навоий | B20: Навоий ш. Низомий кўча 28А уй Эски Прибанк | C20: 14996 | D20: NCR6622 | E20: 803880.04 | F20: 8058.1 | G20: 756371.65 | H20: 7549.2 | I20: 1180248.5 | J20: 11970.45 | K20: 716553.8 | L20: 7201 | M20: 606557.99 | N20: 6064.05 | O20: 830863.17 | P20: 8281.45
A21: Навоий | B21: Навоий савдо комплекси 24/7 | C21: 15896 | D21: NCR6622 | E21: 970772.27 | F21: 9782.05 | G21: 714144.97 | H21: 7132.1 | I21: 652462.1 | J21: 6548.65 | K21: 613039.57 | L21: 6175.75 | M21: 794529.05 | N21: 7947 | O21: 688992.25 | P21: 6899.15
A22: Навоий | B22: Кармана тумани Мирсаид Бахром МФЙ | C22: 16336 | D22: NCR6622 | E22: 1121417.7 | F22: 11248.9 | G22: 1054561.1 | H22: 10611.7 | I22: 1247906.5 | J22: 12649.15 | K22: 913512.12 | L22: 9231.35 | M22: 1349215.6 | N22: 13509.15 | O22: 1003492.5 | P22: 10092.55
A23: Навоий | B23: Нурафшон БХО | C23: 18291 | D23: NCR6622 | E23: 613018.08 | F23: 6124.2 | G23: 576019.17 | H23: 5784.95 | I23: 548221.17 | J23: 5476.65 | K23: 415277.62 | L23: 4181.8 | M23: 739954.51 | N23: 7441.95 | O23: 515259.82 | P23: 5185
A24: Навоий | B24: Навбахор БХО | C24: 21377 | D24: NCR6623 | E24: 581960.22 | F24: 5826.05 | G24: 719362.99 | H24: 7260.25 | I24: 616563.48 | J24: 6319.8 | K24: 325809.66 | L24: 3292.95 | M24: 596149.9 | N24: 5995.9 | O24: 596360.05 | P24: 5996.05
A25: Навоий | B25: Хатирчи БХО | C25: 21375 | D25: NCR6623 | E25: 1654457.9 | F25: 16404.3 | G25: 1349422.1 | H25: 13465.55 | I25: 1111769.8 | J25: 11040.85 | K25: 835221.05 | L25: 8299.35 | M25: 791355.21 | N25: 7843.05 | O25: 828514.13 | P25: 8222.35
A26: Навоий | B26: Навбахор БХО | C26: 21376 | D26: NCR6623 | E26: 2280567.7 | F26: 22640.3 | G26: 2069942.8 | H26: 20593.35 | I26: 2421285.7 | J26: 24149.8 | K26: 1196695.8 | L26: 11887.7 | M26: 2482352.6 | N26: 24677.25 | O26: 2856112.2 | P26: 28410.65
A27: Навоий | B27: Юксалиш БХО | C27: 25729 | D27: NCR6623 | E27: 808033.82 | F27: 8031.85 | G27: 824999.6 | H27: 8247.85 | I27: 1306076.2 | J27: 13019.2 | K27: 608719.78 | L27: 6065.85 | M27: 78953.446 | N27: 804.25 | O27: 36490.939 | P27: 361.3
A28: Навоий | B28: Навоий филиали биносида 24/7 | C28: 26393 | D28: NCR6623 | E28: 1216624.2 | F28: 12216.45 | G28: 914565.52 | H28: 9184.7 | I28: 997472.2 | J28: 10002.2 | K28: 542076.36 | L28: 5541.9 | M28: 763274.28 | N28: 7621.9 | O28: 346439.01 | P28: 3442.45
A29: Навоий | B29: Навоий филиали биносида 24/7 | C29: 39977 | D29: Хюсонг | K29: 0 | L29: 0 | O29: 0 | P29: 0
A30: Навоий | B30: Навоий савдо комплекси 24/7 | C30: 27732 | D30: NCR6623 | E30: 1319969.3 | F30: 13152.5 | G30: 1395133.8 | H30: 13897.7 | I30: 1190885.4 | J30: 11837.25 | K30: 1178656.4 | L30: 11698.1 | M30: 1804835.3 | N30: 17963.25 | O30: 942785.18 | P30: 9374.55
A31: Наманган | B31: Наманган филиали биносида 24/7 | C31: 25702 | D31: NCR6623 | E31: 1690436.2 | F31: 16923.15 | G31: 1899702 | H31: 19201.2 | I31: 2315736.8 | J31: 23390.15 | K31: 1681526.5 | L31: 16943.4 | M31: 2284200.4 | N31: 22883.3 | O31: 2176032.5 | P31: 21734.25
A32: Наманган | B32: (Чорсу БХОда эди) Омборда | C32: 15874 | D32: NCR6622 | E32: 0 | F32: 0 | G32: 0 | H32: 0 | I32: 0 | J32: 0 | K32: 0 | L32: 0 | M32: 0 | N32: 0 | O32: 0 | P32: 0
A33: Наманган | B33: (Чорсу бозори ҳудудида эди) Омборда | C33: 19037 | D33: NCR6622 | E33: 0 | F33: 0 | G33: 0 | H33: 0 | I33: 0 | J33: 0 | K33: 0 | L33: 0 | M33: 0 | N33: 0 | O33: 0 | P33: 0
A34: Наманган | B34: Дўстлик БХО | C34: 21272 | D34: NCR6623 | E34: 1544737.8 | F34: 15453.25 | G34: 1482547.7 | H34: 15102.85 | I34: 1671396.4 | J34: 16933.35 | K34: 1297536.6 | L34: 13149.7 | M34: 1999701.4 | N34: 20221.6 | O34: 1845696 | P34: 18534.55
A35: Наманган | B35: Давлатобод тумани | C35: 39951 | D35: Хюсонг | K35: 0 | L35: 0 | O35: 17778.641 | P35: 59.4
A36: Наманган | B36: Лола БХО | C36: 21273 | D36: NCR6623 | E36: 1539072.5 | F36: 15407.9 | G36: 2971544.1 | H36: 29894 | I36: 2738011.3 | J36: 27759.1 | K36: 1761141.1 | L36: 17728.8 | M36: 2391140.9 | N36: 24125.05 | O36: 3713681.2 | P36: 37488.7
A37: Наманган | B37: (Косонсой БХОда эди) Омборда | C37: 15007 | D37: NCR6622 | E37: 0 | F37: 0 | G37: 0 | H37: 0 | I37: 0 | J37: 0 | K37: 0 | L37: 0 | M37: 0 | N37: 0 | O37: 0 | P37: 0
A38: Наманган | B38: Чорсу БХО | C38: 29292 | D38: NCR6623 | E38: 1785049.6 | F38: 18057.65 | G38: 2454713.7 | H38: 24758.5 | I38: 1748510.5 | J38: 17748.2 | K38: 1238897.4 | L38: 12509.95 | M38: 2105197 | N38: 21448.4 | O38: 2144819.9 | P38: 21621.5
A39: Наманган | B39: Нуробод ошхона | C39: 29293 | D39: NCR6623 | E39: 119321.92 | F39: 1233.15 | G39: 152235.85 | H39: 1547.4 | I39: 173363.57 | J39: 1775.35 | K39: 85654.954 | L39: 895.85 | M39: 172168.24 | N39: 1709.95 | O39: 174944.21 | P39: 1735.95
A40: Самарқанд | B40: (Прибанк 24/7да эди) Омборда | C40: 15042 | D40: NCR6622 | E40: 0 | F40: 0 | G40: 0 | H40: 0 | I40: 0 | J40: 0 | K40: 0 | L40: 0 | M40: 0 | N40: 0 | O40: 0 | P40: 0
A41: Самарқанд | B41: Паст дарғом тумани роват МФЙ | C41: 21627 | D41: NCR6623 | E41: 1009593.8 | F41: 10003.8 | G41: 1153397.4 | H41: 11488.9 | I41: 1214799.2 | J41: 12181.35 | K41: 987145.6 | L41: 9845.45 | M41: 684566.86 | N41: 6793.65 | O41: 1171696.5 | P41: 11638.15
...

Sheet Humo
A1: БХМ номи | B1: Банкомат ўрнатилган манзил | C1: Terminal ID | D1: Bankomat modeli | E1: 2026 йил Январ Чиқим | F1: 2026 йил Январ Даромад | G1: 2026 йил Феврал Чиқим | H1: 2026 йил Феврал Даромад | I1: 2026 йил Март Чиқим | J1: 2026 йил Март Даромад | K1: 2026 йил Апрел Чиқим | L1: 2026 йил Апрел Даромад | M1: 2026 йил Май Чиқим | N1: 2026 йил Май Даромад | O1: 2026 йил Июнь Чиқим | P1: 2026 йил Июнь Даромад
A2: Бухоро | B2: Бухоро филиали биносида 24/7 | C2: 157A0AK3 | D2: H68VL (GRG) | E2: 834810.68 | F2: 7871.2 | G2: 822700.15 | H2: 7654 | I2: 963093.5 | J2: 9045.1 | K2: 860677.53 | L2: 7816.1 | M2: 843850.08 | N2: 7770.9 | O2: 744726.94 | P2: 6855.7
A3: Бухоро | B3: (Мохитабон БХОда эди) Ёпилган - Ғиждувонга кўчирилади | C3: 157A05DK | D3: Cieno C2040 | E3: 0 | F3: 0 | G3: 0 | H3: 0 | I3: 0 | J3: 0 | K3: 0 | L3: 0 | M3: 0 | N3: 0 | O3: 0 | P3: 0
A4: Бухоро | B4: (МЧСда эди) Ғиждувон деҳқон бозорида | C4: 157A05DJ | D4: Cieno C2040 | E4: 0 | F4: 0 | G4: 0 | H4: 0 | I4: 0 | J4: 0 | K4: 0 | L4: 0 | M4: 0 | N4: 0 | O4: 0 | P4: 0
A5: Бухоро | B5: Ғиждувон деҳқон бозори | C5: 1570001V | D5: Cieno C2040 | K5: 0 | L5: 0 | M5: 0 | N5: 0 | O5: 134935.26 | P5: 1188.5
A6: Бухоро | B6: Когон БХО | C6: 157A062W | D6: Cieno C2040 | E6: 432120.04 | F6: 4161.9 | G6: 191032.25 | H6: 1753.7 | I6: 1002191.5 | J6: 9448.4 | K6: 630274.84 | L6: 5956.7 | M6: 763714.64 | N6: 7364.9 | O6: 766186.51 | P6: 7388.8
A7: Бухоро | B7: Buxoro shahar Pridaskir ko'chasi 5A uy | C7: 1570000E | D7: NCR6623 | E7: 949401.11 | F7: 8943.3 | G7: 707126.43 | H7: 6374.4 | I7: 1095236 | J7: 10319.1 | K7: 538904.64 | L7: 5161.6 | M7: 145953.07 | N7: 1333 | O7: 968891.68 | P7: 8969.6
A8: Бухоро | B8: Бухоро т. Зарманоқ мфй | C8: 157A0B8M | D8: Cieno C2040 | E8: 315574.36 | F8: 3087.4 | G8: 287738.63 | H8: 2820.6 | I8: 355594.87 | J8: 3433.4 | K8: 282569.1 | L8: 2753.9 | M8: 346587.82 | N8: 3378.3 | O8: 250566.47 | P8: 2326.8
A9: Бухоро | B9: Қоракўл БХО | C9: 157A0B8L | D9: Cieno C2040 | E9: 358152.39 | F9: 3257.8 | G9: 505818.32 | H9: 4775.4 | I9: 958113.75 | J9: 8800.5 | K9: 0 | L9: 0 | M9: 0 | N9: 0 | O9: 413115.74 | P9: 3905.6
A10: Бухоро | B10: Ғиждувон БХО | C10: 157A0C0U | D10: NCR6623 | E10: 321311.21 | F10: 3039.6 | G10: 830763.14 | H10: 7755.6 | I10: 1206341.1 | J10: 11574.2 | K10: 540502.06 | L10: 5240.3 | M10: 1319934.6 | N10: 12583.5 | O10: 1661374.6 | P10: 15923
A11: Бухоро | B11: Сомоний БХО | C11: 157A0C0V | D11: NCR6623 | E11: 196051.43 | F11: 1923.7 | G11: 250907.28 | H11: 2416.6 | I11: 391208.15 | J11: 3752.7 | K11: 350816.98 | L11: 3321.7 | M11: 399434.02 | N11: 3826 | O11: 0 | P11: 0
A12: Бухоро | B12: (Romitan tuman Marziya MFYда эди) Омборда носоз - списат бўлади | C12: 157A05D2 | D12: Cieno C2040 | E12: 0 | F12: 0 | G12: 0 | H12: 0 | I12: 0 | J12: 0 | K12: 0 | L12: 0 | M12: 0 | N12: 0 | O12: 0 | P12: 0
A13: Қарши | B13: Қарши филиал биносида 24/7 | C13: 157A05AT | D13: Cieno C2040 | E13: 785539.81 | F13: 7537.35 | G13: 494253.97 | H13: 4656.95 | I13: 1224731.8 | J13: 11734.75 | K13: 834897.44 | L13: 7659.5 | M13: 591829.95 | N13: 5598.8 | O13: 1025986.4 | P13: 9881.8
A14: Қарши | B14: Миришкор БХО | C14: 157A05AU | D14: Cieno C2040 | E14: 661899.07 | F14: 6531.9 | G14: 560837.35 | H14: 5552.9 | I14: 483951.83 | J14: 4773.6 | K14: 309638.51 | L14: 2988.8 | M14: 535335.43 | N14: 5269.2 | O14: 662073 | P14: 6496.1
A15: Қарши | B15: Насаф БХО | C15: 157A05ZE | D15: Cieno C2040 | E15: 530270.03 | F15: 4673 | G15: 288914.12 | H15: 2775 | I15: 6039.7402 | J15: 59.8 | K15: 0 | L15: 0 | M15: 309822.24 | N15: 2959.3 | O15: 668589.6 | P15: 6250
A16: Қарши | B16: Косон БХО | C16: 157A06XF | D16: Cieno C2040 | E16: 922933.66 | F16: 8689.6 | G16: 976731.61 | H16: 9488.4 | I16: 1142837.6 | J16: 10797.9 | K16: 678147.64 | L16: 6312.3 | M16: 1201754.1 | N16: 11552.1 | O16: 1113367.8 | P16: 10590.2
A17: Қарши | B17: Қарши филиал биносида 24/7 | C17: 157A0AKF | D17: H68VL (GRG) | E17: 224005.68 | F17: 2072.8 | G17: 45078.857 | H17: 443.3 | I17: 6595.2347 | J17: 65.3 | K17: 403.996 | L17: 4 | M17: 282.7972 | N17: 2.8 | O17: 118033.09 | P17: 1011.1
... A36: Наманган | B36: Наманган филиали биносида 24/7 | C36: 157A0AJY | D36: H68VL (GRG) | E36: 1154450.5 | F36: 10984.2 | G36: 1112417.7 | H36: 10391.7 | I36: 1143719.9 | J36: 11004.5 | K36: 917039.94 | L36: 8614.9 | M36: 1072827.8 | N36: 10375.4 | O36: 740596.4 | P36: 7098.8
A37: Наманган | B37: Янгиқўрғон дўкони | C37: 15700003 | D37: Cieno C2040 | E37: 1271393.2 | F37: 12059.1 | G37: 1146732.5 | H37: 10900.6 | I37: 1995234.3 | J37: 18888.5 | K37: 1495569.7 | L37: 13822.6 | M37: 1756172.8 | N37: 16381.5 | O37: 1486763.3 | P37: 13714.8
A38: Наманган | B38: Чорсу бозори ҳудудида 24/7 | C38: 1570001L | D38: Cieno C2040 | E38: 680320.39 | F38: 6506.9 | G38: 225380.14 | H38: 2014.2 | I38: 126030.67 | J38: 1129.2 | K38: 647095.33 | L38: 6023.3 | M38: 711532.55 | N38: 6805 | O38: 655562.71 | P38: 6092.2
A39: Самарқанд | B39: Прибанк 24/7 | C39: 157A05AN | D39: Cieno C2040 | E39: 93923.98 | F39: 919.75 | G39: 231581.08 | H39: 2018.6 | I39: 652082.14 | J39: 5880.95 | K39: 503265.62 | L39: 4352.5 | M39: 1083255.7 | N39: 10033.65 | O39: 246356.16 | P39: 2188.9
A40: Самарқанд | B40: Самарқанд ш. Спитамин Шох кўча 18 уй | C40: 157A05BF | D40: Cieno C2040 | E40: 916539.14 | F40: 8555.9 | G40: 773056.69 | H40: 7364.2 | I40: 637419.9 | J40: 5946.7 | K40: 1400538.9 | L40: 12947.7 | M40: 2026028 | N40: 18465.7 | O40: 1157783.6 | P40: 10917.6
A41: Самарқанд | B41: Оқдарё тумани Лойиш шахарчаси БХО | C41: 157A0607 | D41: Cieno C2040 | E41: 1403082 | F41: 13678.5 | G41: 1998812.6 | H41: 19214.1 | I41: 1838187.2 | J41: 17741.7 | K41: 1562804.5 | L41: 14792 | M41: 2244580.1 | N41: 21550.3 | O41: 1881393.9 | P41: 18064.2
A42: Самарқанд | B42: Мархабо БХО | C42: 157A0748 | D42: Cieno C2040 | E42: 1500141.8 | F42: 13734.6 | G42: 1978281.3 | H42: 18532.1 | I42: 2227597.4 | J42: 20516.4 | K42: 889468.74 | L42: 8156.8 | M42: 1510326.6 | N42: 14150.1 | O42: 1461899.4 | P42: 13261.9
A43: Самарқанд | B43: Самарқанд ш. Спитамин Шох кўча 18 уй | C43: 157A0AVN | D43: Cieno C2040 | E43: 815913.72 | F43: 7726.5 | G43: 1075036.4 | H43: 10089.1 | I43: 1221805.6 | J43: 11461.5 | K43: 210394.8 | L43: 2004.7 | M43: 227013.86 | N43: 2087.8 | O43: 1294757.6 | P43: 12047.4
A44: Самарқанд | B44: Пасдарғом тумани Ўртачархин МФЙ | C44: 157A0AVM | D44: Cieno C2040 | E44: 1018286.4 | F44: 9991.8 | G44: 1328302.1 | H44: 12899.9 | I44: 1630920.7 | J44: 15800.5 | K44: 1241127.5 | L44: 11927.8 | M44: 1534821.8 | N44: 14869.6 | O44: 1647987.9 | P44: 15837.3
A45: Самарқанд | B45: Самарқанд филиали биносида 24/7 | C45: 157A0AK9 | D45: H68VL (GRG) | E45: 909532.39 | F45: 8664 | G45: 1350190.2 | H45: 12402.4 | I45: 939485.09 | J45: 8408.8 | K45: 776459.4 | L45: 7354.6 | M45: 45984.895 | N45: 455.2 | O45: 0 | P45: 0
A46: Самарқанд | B46: Каттақўрғон БХО | C46: 157A0BZQ | D46: NCR6623 | E46: 530353.19 | F46: 5207.4 | G46: 338151.12 | H46: 3282 | I46: 0 | J46: 0 | K46: 0 | L46: 0 | M46: 459635.56 | N46: 4487.8 | O46: 744962.27 | P46: 7228.9
A47: Гулистон | B47: Янгибозор 24/7 | C47: 157A05AJ | D47: Cieno C2040 | E47: 1932587.9 | F47: 18550.5 | G47: 2147707.8 | H47: 20665.9 | I47: 3321503.7 | J47: 31385.6 | K47: 2775127.9 | L47: 26422.1 | M47: 2255592.4 | N47: 21043.2 | O47: 2970447.4 | P47: 28038.2
A48: Гулистон | B48: Гулистон шахар хокимияти яқинида 24/7 | C48: 157A060I | D48: Cieno C2040 | E48: 736482.5 | F48: 6896.2 | G48: 556183.74 | H48: 5163 | I48: 682641.68 | J48: 6419.9 | K48: 600657.23 | L48: 5567.8 | M48: 673911.15 | N48: 6395.6 | O48: 567473.78 | P48: 5218.4
A49: Гулистон | B49: Хумо БХО | C49: 157A06YW | D49: Cieno C2040 | E49: 1242551 | F49: 12043.1 | G49: 581173.84 | H49: 5489.85 | I49: 1374801.2 | J49: 13087.85 | K49: 1033764.3 | L49: 9960.4 | M49: 910136.49 | N49: 8731.4 | O49: 1744629.7 | P49: 16727.4
... A53: Термиз | B53: Жарқўрғон БХО | C53: 157A05AK | D53: Cieno C2040 | E53: 127542.54 | F53: 1260.8 | G53: 224190.53 | H53: 2116.8 | I53: 259764.76 | J53: 2542.3 | K53: 149772.66 | L53: 1390.3 | M53: 160590.2 | N53: 1550.7 | O53: 251162.56 | P53: 2394.3
A54: Термиз | B54: Юбилейний Ақлли бекат | C54: 15700002 | D54: NCR6623 | E54: 509859.82 | F54: 4826.2 | G54: 542972.26 | H54: 4835.4 | I54: 1133197.3 | J54: 10411.3 | K54: 775586.56 | L54: 7040.2 | M54: 1476960.7 | N54: 13621.4 | O54: 997923.05 | P54: 9346.3
A55: Термиз | B55: Прибанк 24/7 | C55: 157A05ZP | D55: Cieno C2040 | E55: 0 | F55: 0 | G55: 0 | H55: 0 | I55: 0 | J55: 0 | K55: 0 | L55: 0 | M55: 424932.19 | N55: 3405.9 | O55: 353407.99 | P55: 3357.1
A56: Термиз | B56: Денов БХО | C56: 157A07AF | D56: Cieno C2040 | E56: 641852.25 | F56: 6252.8 | G56: 613642.29 | H56: 5910.9 | I56: 764211.56 | J56: 7492.8 | K56: 553657.42 | L56: 5384.4 | M56: 496036.69 | N56: 4812.6 | O56: 1502580.7 | P56: 14725.4
A57: Термиз | B57: Термиз филиали биносида 24/7 | C57: 157A0AN0 | D57: H68VL (GRG) | E57: 1220012.1 | F57: 11426.9 | G57: 895542.18 | H57: 8417.1 | I57: 967897 | J57: 8300.2 | K57: 541334.59 | L57: 5210.3 | M57: 687151.07 | N57: 6427.8 | O57: 1000576.3 | P57: 9589.8
A58: Термиз | B58: Бақтрия савдо комплекси | C58: 157A0CCR | D58: NCR6623 | E58: 1318179.1 | F58: 10489.8 | G58: 825092.09 | H58: 7510.7 | I58: 1299024.1 | J58: 11952.8 | K58: 703792.36 | L58: 6436.2 | M58: 1247853.6 | N58: 11451.2 | O58: 1085816.4 | P58: 9794.4
A59: Термиз | B59: Юбилейний бекати 24/7 | C59: 157A05ZO | D59: Cieno C2040 | E59: 836145.66 | F59: 7790.9 | G59: 626654.17 | H59: 5831 | I59: 452499.19 | J59: 4210 | K59: 24142.289 | L59: 210.7 | M59: 572268.28 | N59: 5369.5 | O59: 646265.78 | P59: 6173.9
A60: МАБ | B60: Гидропроект 24/7 | C60: 157A05JA | D60: Cieno C2040 | E60: 217466.57 | F60: 1875.9 | G60: 106436.93 | H60: 973.4 | I60: 186095.06 | J60: 1591.6 | K60: 277456.31 | L60: 2386.2 | M60: 227283.94 | N60: 1708.7 | O60: 136005.45 | P60: 1095.3
A61: МАБ | B61: Ўзбекгидроэнергия | C61: 1570001R | D61: Cieno C2040 | E61: 0 | F61: 0 | G61: 0 | H61: 0 | I61: 11503.886 | J61: 113.7 | K61: 128964.96 | L61: 1238.4035 | M61: 189657.03 | N61: 1821.8361 | O61: 58492.223 | P61: 577.32772
...

Sheet 2026 iyul uzcard
A1: TERM_ID | B1: SUM(DTL_VALUE) | C1: SUM(DTL_VALUE_DT) | D1: SUM(DTL_VALUE_KT) | E1: SUM(AMOUNT) | F1: SUM(AMOUNT_DT) | G1: SUM(AMOUNT_KT) | H1: CASH_AMOUNT | I1: CASH_AMOUNT_DT | J1: CASH_AMOUNT_KT | K1: SRV_DEP_CODE | L1: SRV_DEP_NAME
A2: 15906 | B2: 4101625 | C2: 4097625 | D2: 4000 | E2: 405131625 | F2: 404000 | G2: 404727625 | H2: 401030000 | I2: -3693625 | J2: 404723625 | K2: 11284 | L2: Сирдарё БХМ
A3: 22374 | B3: 3798600 | C3: 3789100 | D3: 9500 | E3: 382708600 | F3: 959500 | G3: 381749100 | H3: 378910000 | I3: -2829600 | J3: 381739600 | K3: 11285 | L3: Фарғона БХМ
A4: 29638 | B4: 14776050 | C4: 14776050 | D4: 0 | E4: 1467266050 | F4: 0 | G4: 1467266050 | H4: 1452490000 | I4: -14776050 | J4: 1467266050 | K4: 11285 | L4: Фарғона БХМ
A5: 39996 | B5: 8298700 | C5: 8298700 | D5: 0 | E5: 855963100 | F5: 16111500 | G5: 839851600 | H5: 847664400 | I5: 7812800 | J5: 839851600 | K5: 11279 | L5: Қарши БХМ
A6: 28433 | B6: 108300 | C6: 108300 | D6: 0 | E6: 148978300 | F6: 0 | G6: 148978300 | H6: 148870000 | I6: -108300 | J6: 148978300 | K6: 10696 | L6: "Shayxontoxur" bank xizmatlari
A7: 34789 | B7: 6889850 | C7: 6889850 | D7: 0 | E7: 676179850 | F7: 0 | G7: 676179850 | H7: 669290000 | I7: -6889850 | J7: 676179850 | K7: 11287 | L7: Қорақалпоғистон БХМ
A8: 26088 | B8: 4201300 | C8: 4201300 | D8: 0 | E8: 416671300 | F8: 0 | G8: 416671300 | H8: 412470000 | I8: -4201300 | J8: 416671300 | K8: 11283 | L8: Сурхондарё БХМ
A9: 21147 | B9: 7970650 | C9: 7930650 | D9: 40000 | E9: 797100650 | F9: 4040000 | G9: 793060650 | H9: 789130000 | I9: -3890650 | J9: 793020650 | K9: 11279 | L9: Қарши БХМ
A10: 25736 | B10: 3225950 | C10: 3225950 | D10: 0 | E10: 306675950 | F10: 0 | G10: 306675950 | H10: 303450000 | I10: -3225950 | J10: 306675950 | K10: 11291 | L10: Зангиота БХМ
A11: 21299 | B11: 5587850 | C11: 5587850 | D11: 0 | E11: 560307850 | F11: 0 | G11: 560307850 | H11: 554720000 | I11: -5587850 | J11: 560307850 | K11: 11279 | L11: Қарши БХМ
A12: 21533 | B12: 7145900 | C12: 7145900 | D12: 0 | E12: 707345900 | F12: 0 | G12: 707345900 | H12: 700200000 | I12: -7145900 | J12: 707345900 | K12: 11284 | L12: Сирдарё БХМ
A13: 22015 | B13: 1507000 | C13: 1507000 | D13: 0 | E13: 149707000 | F13: 0 | G13: 149707000 | H13: 148200000 | I13: -1507000 | J13: 149707000 | K13: 11291 | L13: Зангиота БХМ
... A122: 29593 | B122: 12219400 | C122: 12219400 | D122: 0 | E122: 1188279400 | F122: 0 | G122: 1188279400 | H122: 1176060000 | I122: -12219400 | J122: 1188279400 | K122: 11287 | L122: Қорақалпоғистон БХМ

Sheet 2026 iyul humo
A1: TERM_ID | B1: SUM(DTL_VALUE) | C1: SUM(DTL_VALUE_DT) | D1: SUM(DTL_VALUE_KT) | E1: SUM(AMOUNT) | F1: SUM(AMOUNT_DT) | G1: SUM(AMOUNT_KT) | H1: CASH_AMOUNT | I1: CASH_AMOUNT_DT | J1: CASH_AMOUNT_KT | K1: SRV_DEP_CODE | L1: SRV_DEP_NAME
A2: 15700003 | B2: 15059500 | C2: 0 | D2: 15059500 | E2: 1507499500 | F2: 0 | G2: 1507499500 | H2: 1492440000 | I2: 0 | J2: 1492440000 | K2: 11281 | L2: Наманган БХМ
A3: 157A05JA | B3: 2153300 | C3: 0 | D3: 2153300 | E3: 204443300 | F3: 0 | G3: 204443300 | H3: 202290000 | I3: 0 | J3: 202290000 | K3: 10725 | L3: Toshkent shahar BXM
A4: 157A0AVN | B4: 5661500 | C4: 0 | D4: 5661500 | E4: 563101500 | F4: 0 | G4: 563101500 | H4: 557440000 | I4: 0 | J4: 557440000 | K4: 11282 | L4: Самарқанд БХМ
A5: 1570000T | B5: 16662550 | C5: 0 | D5: 16662550 | E5: 1659672550 | F5: 0 | G5: 1659672550 | H5: 1643010000 | I5: 0 | J5: 1643010000 | K5: 11290 | L5: Шаҳрисабз БХМ
A6: 157A05ZE | B6: 4918100 | C6: 0 | D6: 4918100 | E6: 488938100 | F6: 0 | G6: 488938100 | H6: 484020000 | I6: 0 | J6: 484020000 | K6: 11279 | L6: Қарши БХМ
A7: 157A0BYU | B7: 3727750 | C7: 0 | D7: 3727750 | E7: 351682750 | F7: 0 | G7: 351682750 | H7: 347955000 | I7: 0 | J7: 347955000 | K7: 11284 | L7: Сирдарё БХМ
A8: 157A05ZA | B8: 2966700 | C8: 0 | D8: 2966700 | E8: 278766700 | F8: 0 | G8: 278766700 | H8: 275800000 | I8: 0 | J8: 275800000 | K8: 11281 | L8: Наманган БХМ
A9: 157A0C51 | B9: 2386800 | C9: 0 | D9: 2386800 | E9: 295286800 | F9: 0 | G9: 295286800 | H9: 292900000 | I9: 0 | J9: 292900000 | K9: 11286 | L9: Хоразм БХМ
A10: 157A05AO | B10: 16119150 | C10: 0 | D10: 16119150 | E10: 1596759150 | F10: 0 | G10: 1596759150 | H10: 1580640000 | I10: 0 | J10: 1580640000 | K10: 11281 | L10: Наманган БХМ
A11: 15700002 | B11: 3650800 | C11: 0 | D11: 3650800 | E11: 356860800 | F11: 0 | G11: 356860800 | H11: 353210000 | I11: 0 | J11: 353210000 | K11: 11283 | L11: Сурхондарё БХМ
A12: 157A0B8M | B12: 3302100 | C12: 0 | D12: 3302100 | E12: 332162100 | F12: 0 | G12: 332162100 | H12: 328860000 | I12: 0 | J12: 328860000 | K12: 11278 | L12: Бухоро БХМ
A13: 1570000E | B13: 8537350 | C13: 0 | D13: 8537350 | E13: 852497350 | F13: 0 | G13: 852497350 | H13: 843960000 | I13: 0 | J13: 843960000 | K13: 11278 | L13: Бухоро БХМ
A14: 157A060L | B14: 25000700 | C14: 0 | D14: 25000700 | E14: 2489420700 | F14: 0 | G14: 2489420700 | H14: 2464420000 | I14: 0 | J14: 2464420000 | K14: 11286 | L14: Хоразм БХМ
A15: 157A0CWR | B15: 13054550 | C15: 3000 | D15: 13051550 | E15: 1290804550 | F15: 303000 | G15: 1290501550 | H15: 1277750000 | I15: 300000 | J15: 1277450000 | K15: 11291 | L15: Зангиота БХМ
A16: 157A06XN | B16: 2153400 | C16: 0 | D16: 2153400 | E16: 215568400 | F16: 0 | G16: 215568400 | H16: 213415000 | I16: 0 | J16: 213415000 | K16: 11285 | L16: Фарғона БХМ
A17: 157A0CHK | B17: 18397200 | C17: 0 | D17: 18397200 | E17: 1820437200 | F17: 0 | G17: 1820437200 | H17: 1802040000 | I17: 0 | J17: 1802040000 | K17: 11291 | L17: Зангиота БХМ
A18: 157A073M | B18: 8840400 | C18: 60000 | D18: 8780400 | E18: 883500400 | F18: 6060000 | G18: 877440400 | H18: 874660000 | I18: 6000000 | J18: 868660000 | K18: 11288 | L18: Жиззах БХМ
A19: 157A0C29 | B19: 2701850 | C19: 0 | D19: 2701850 | E19: 255571850 | F19: 0 | G19: 255571850 | H19: 252870000 | I19: 0 | J19: 252870000 | K19: 11279 | L19: Қарши БХМ
A20: 15700006 | B20: 14568500 | C20: 10000 | D20: 14558500 | E20: 1427688500 | F20: 1010000 | G20: 1426678500 | H20: 1413120000 | I20: 1000000 | J20: 1412120000 | K20: 11285 | L20: Фарғона БХМ
A21: 157A0AKE | B21: 25961000 | C21: -19650 | D21: 25980650 | E21: 2595036000 | F21: 2345350 | G21: 2592690650 | H21: 2569075000 | I21: 2365000 | J21: 2566710000 | K21: 11290 | L21: Шаҳрисабз БХМ
A22: 157A0628 | B22: 10401200 | C22: 0 | D22: 10401200 | E22: 1043851200 | F22: 0 | G22: 1043851200 | H22: 1033450000 | I22: 0 | J22: 1033450000 | K22: 11280 | L22: Навоий БХМ
A23: 157A07AF | B23: 7422050 | C23: 0 | D23: 7422050 | E23: 747372050 | F23: 0 | G23: 747372050 | H23: 739950000 | I23: 0 | J23: 739950000 | K23: 11283 | L23: Сурхондарё БХМ
A24: 157A0CHJ | B24: 14239100 | C24: 0 | D24: 14239100 | E24: 1403359100 | F24: 0 | G24: 1403359100 | H24: 1389120000 | I24: 0 | J24: 1389120000 | K24: 10715 | L24: "Oxangaron" bank xizmatlari o
A25: 157A0AFH | B25: 649710 | C25: -340040 | D25: 989750 | E25: 129153710 | F25: 33663960 | G25: 95489750 | H25: 128504000 | I25: 34004000 | J25: 94500000 | K25: 10725 | L25: Toshkent shahar BXM
A26: 157A0BZ5 | B26: 7498250 | C26: 0 | D26: 7498250 | E26: 747178250 | F26: 0 | G26: 747178250 | H26: 739680000 | I26: 0 | J26: 739680000 | K26: 11280 | L26: Навоий БХМ
A27: 15700001 | B27: 438050 | C27: 0 | D27: 438050 | E27: 690408050 | F27: 0 | G27: 690408050 | H27: 689970000 | I27: 0 | J27: 689970000 | K27: 10725 | L27: Toshkent shahar BXM
A28: 1570000W | B28: 477800 | C28: 0 | D28: 477800 | E28: 795657800 | F28: 0 | G28: 795657800 | H28: 795180000 | I28: 0 | J28: 795180000 | K28: 10725 | L28: Toshkent shahar BXM
A29: 157A05CL | B29: 14777850 | C29: 0 | D29: 14777850 | E29: 1474367850 | F29: 0 | G29: 1474367850 | H29: 1459590000 | I29: 0 | J29: 1459590000 | K29: 11286 | L29: Хоразм БХМ
A30: 157A0B8L | B30: 4229150 | C30: 0 | D30: 4229150 | E30: 423059150 | F30: 0 | G30: 423059150 | H30: 418830000 | I30: 0 | J30: 418830000 | K30: 10668 | L30: "Qorako‘l" bank xizmatlari ofi
A31: 157A0BYK | B31: 7935400 | C31: 0 | D31: 7935400 | E31: 798475400 | F31: 0 | G31: 798475400 | H31: 790540000 | I31: 0 | J31: 790540000 | K31: 10676 | L31: "Xatirchi" bank xizmatlari ofi
A32: 157A059V | B32: 5465650 | C32: 0 | D32: 5465650 | E32: 533745650 | F32: 0 | G32: 533745650 | H32: 528280000 | I32: 0 | J32: 528280000 | K32: 11285 | L32: Фарғона БХМ
A33: 15700023 | B33: 7300 | C33: 0 | D33: 7300 | E33: 737300 | F33: 0 | G33: 737300 | H33: 730000 | I33: 0 | J33: 730000 | K33: 10725 | L33: Toshkent shahar BXM
A34: 157A05YH | B34: 11648650 | C34: 0 | D34: 11648650 | E34: 1154408650 | F34: 0 | G34: 1154408650 | H34: 1142760000 | I34: 0 | J34: 1142760000 | K34: 11281 | L34: Наманган БХМ
A35: 157A076O | B35: 12358500 | C35: 0 | D35: 12358500 | E35: 1224568500 | F35: 0 | G35: 1224568500 | H35: 1212210000 | I35: 0 | J35: 1212210000 | K35: 11281 | L35: Наманган БХМ
A36: 157A0AJX | B36: 2835350 | C36: 0 | D36: 2835350 | E36: 281295350 | F36: 0 | G36: 281295350 | H36: 278460000 | I36: 0 | J36: 278460000 | K36: 11288 | L36: Жиззах БХМ
A37: 1570000Q | B37: 7949300 | C37: 0 | D37: 7949300 | E37: 783279300 | F37: 0 | G37: 783279300 | H37: 775330000 | I37: 0 | J37: 775330000 | K37: 11290 | L37: Шаҳрисабз БХМ
A38: 157A0AFP | B38: 2429800 | C38: 7500 | D38: 2422300 | E38: 244409800 | F38: 757500 | G38: 243652300 | H38: 241980000 | I38: 750000 | J38: 241230000 | K38: 10706 | L38: "Mirobod" bank xizmatlari ofis
A39: 157A0AH2 | B39: 15807450 | C39: -606900 | D39: 16414350 | E39: 2384267450 | F39: 753193100 | G39: 1631074350 | H39: 2368460000 | I39: 753800000 | J39: 1614660000 | K39: 11284 | L39: Сирдарё БХМ
A40: 157A0DOC | B40: 18811750 | C40: 0 | D40: 18811750 | E40: 1876961750 | F40: 0 | G40: 1876961750 | H40: 1858150000 | I40: 0 | J40: 1858150000 | K40: 11280 | L40: Навоий БХМ
...

Sheet 2026 iyul vash
A1: TERM_ID | B1: SUM(DTL_VALUE) | C1: SUM(DTL_VALUE_DT) | D1: SUM(DTL_VALUE_KT) | E1: SUM(AMOUNT) | F1: SUM(AMOUNT_DT) | G1: SUM(AMOUNT_KT) | H1: CASH_AMOUNT | I1: CASH_AMOUNT_DT | J1: CASH_AMOUNT_KT | K1: SRV_DEP_CODE | L1: SRV_DEP_NAME
A2: TBATM041 | B2: 110 | C2: 0 | D2: 110 | E2: 11110 | F2: 0 | G2: 11110 | H2: 11000 | I2: 0 | J2: 11000 | K2: 11284 | L2: Сирдарё БХМ
A3: TBATM040 | B3: 59000 | C3: 0 | D3: 59000 | E3: 5959000 | F3: 0 | G3: 5959000 | H3: 5900000 | I3: 0 | J3: 5900000 | K3: 11284 | L3: Сирдарё БХМ
A4: TBATM064 | B4: 24610 | C4: 0 | D4: 24610 | E4: 2485610 | F4: 0 | G4: 2485610 | H4: 2461000 | I4: 0 | J4: 2461000 | K4: 10725 | L4: Toshkent shahar BXM
A5: TBATM027 | B5: 728110 | C5: 0 | D5: 728110 | E5: 73539110 | F5: 0 | G5: 73539110 | H5: 72811000 | I5: 0 | J5: 72811000 | K5: 11281 | L5: Наманган БХМ
A6: TBATM044 | B6: 160 | C6: 0 | D6: 160 | E6: 16160 | F6: 0 | G6: 16160 | H6: 16000 | I6: 0 | J6: 16000 | K6: 10718 | L6: "Parvoz" bank xizmatlari ofisi
A7: TBATM011 | B7: 10200 | C7: 0 | D7: 10200 | E7: 1030200 | F7: 0 | G7: 1030200 | H7: 1020000 | I7: 0 | J7: 1020000 | K7: 11279 | L7: Қарши БХМ
A8: TBATM007 | B8: 5000 | C8: 0 | D8: 5000 | E8: 505000 | F8: 0 | G8: 505000 | H8: 500000 | I8: 0 | J8: 500000 | K8: 11291 | L8: Зангиота БХМ
A9: TBATM024 | B9: 656510 | C9: 0 | D9: 656510 | E9: 66307510 | F9: 0 | G9: 66307510 | H9: 65651000 | I9: 0 | J9: 65651000 | K9: 11284 | L9: Сирдарё БХМ
A10: TBATM066 | B10: 51310 | C10: 0 | D10: 51310 | E10: 5182310 | F10: 0 | G10: 5182310 | H10: 5131000 | I10: 0 | J10: 5131000 | K10: 10706 | L10: "Mirobod" bank xizmatlari ofis
A11: TBATM001 | B11: 23700 | C11: 0 | D11: 23700 | E11: 2393700 | F11: 0 | G11: 2393700 | H11: 2370000 | I11: 0 | J11: 2370000 | K11: 10725 | L11: Toshkent shahar BXM

Sheet 2026 iyun vash
A1: TERM_ID | B1: SUM(DTL_VALUE) | C1: SUM(DTL_VALUE_DT) | D1: SUM(DTL_VALUE_KT) | E1: SUM(AMOUNT) | F1: SUM(AMOUNT_DT) | G1: SUM(AMOUNT_KT) | H1: CASH_AMOUNT | I1: CASH_AMOUNT_DT | J1: CASH_AMOUNT_KT | K1: SRV_DEP_CODE | L1: SRV_DEP_NAME
A2: TBATM040 | B2: 41000 | C2: 0 | D2: 41000 | E2: 4141000 | F2: 0 | G2: 4141000 | H2: 4100000 | I2: 0 | J2: 4100000 | K2: 11284 | L2: Сирдарё БХМ
A3: TBATM027 | B3: 262300 | C3: 0 | D3: 262300 | E3: 26492300 | F3: 0 | G3: 26492300 | H3: 26230000 | I3: 0 | J3: 26230000 | K3: 11281 | L3: Наманган БХМ
A4: TBATM044 | B4: 1500 | C4: 0 | D4: 1500 | E4: 151500 | F4: 0 | G4: 151500 | H4: 150000 | I4: 0 | J4: 150000 | K4: 10718 | L4: "Parvoz" bank xizmatlari ofisi
A5: TBATM060 | B5: 2500 | C5: 0 | D5: 2500 | E5: 252500 | F5: 0 | G5: 252500 | H5: 250000 | I5: 0 | J5: 250000 | K5: 10725 | L5: Toshkent shahar BXM
A6: TBATM011 | B6: 71700 | C6: 0 | D6: 71700 | E6: 7241700 | F6: 0 | G6: 7241700 | H6: 7170000 | I6: 0 | J6: 7170000 | K6: 11279 | L6: Қарши БХМ
A7: TBATM007 | B7: 76500 | C7: 0 | D7: 76500 | E7: 7726500 | F7: 0 | G7: 7726500 | H7: 7650000 | I7: 0 | J7: 7650000 | K7: 11291 | L7: Зангиота БХМ
A8: TBATM043 | B8: 27500 | C8: 0 | D8: 27500 | E8: 2777500 | F8: 0 | G8: 2777500 | H8: 2750000 | I8: 0 | J8: 2750000 | K8: 10725 | L8: Toshkent shahar BXM
A9: TBATM049 | B9: 3000 | C9: 0 | D9: 3000 | E9: 303000 | F9: 0 | G9: 303000 | H9: 300000 | I9: 0 | J9: 300000 | K9: 11287 | L9: Қорақалпоғистон БХМ
A10: TBATM024 | B10: 1275470 | C10: 0 | D10: 1275470 | E10: 128822470 | F10: 0 | G10: 128822470 | H10: 127547000 | I10: 0 | J10: 127547000 | K10: 11284 | L10: Сирдарё БХМ
A11: TBATM066 | B11: 3300 | C11: 0 | D11: 3300 | E11: 333300 | F11: 0 | G11: 333300 | H11: 330000 | I11: 0 | J11: 330000 | K11: 10706 | L11: "Mirobod" bank xizmatlari ofis
A12: TBATM001 | B12: 183820 | C12: 0 | D12: 183820 | E12: 38265820 | F12: 0 | G12: 38265820 | H12: 38082000 | I12: 0 | J12: 38082000 | K12: 10725 | L12: Toshkent shahar BXM

Sheet 2026 may vash
A1: TERM_ID | B1: SUM(DTL_VALUE) | C1: SUM(DTL_VALUE_DT) | D1: SUM(DTL_VALUE_KT) | E1: SUM(AMOUNT) | F1: SUM(AMOUNT_DT) | G1: SUM(AMOUNT_KT) | H1: CASH_AMOUNT | I1: CASH_AMOUNT_DT | J1: CASH_AMOUNT_KT | K1: SRV_DEP_CODE | L1: SRV_DEP_NAME
A2: TBATM040 | B2: 110 | C2: 0 | D2: 110 | E2: 11110 | F2: 0 | G2: 11110 | H2: 11000 | I2: 0 | J2: 11000 | K2: 11284 | L2: Сирдарё БХМ
A3: TBATM064 | B3: 16500 | C3: 0 | D3: 16500 | E3: 1666500 | F3: 0 | G3: 1666500 | H3: 1650000 | I3: 0 | J3: 1650000 | K3: 10725 | L3: Toshkent shahar BXM
A4: TBATM027 | B4: 120000 | C4: 0 | D4: 120000 | E4: 12120000 | F4: 0 | G4: 12120000 | H4: 12000000 | I4: 0 | J4: 12000000 | K4: 11281 | L4: Наманган БХМ
A5: TBATM044 | B5: 9180 | C5: 0 | D5: 9180 | E5: 927180 | F5: 0 | G5: 927180 | H5: 918000 | I5: 0 | J5: 918000 | K5: 10718 | L5: "Parvoz" bank xizmatlari ofisi
A6: TBATM060 | B6: 3000 | C6: 0 | D6: 3000 | E6: 303000 | F6: 0 | G6: 303000 | H6: 300000 | I6: 0 | J6: 300000 | K6: 10725 | L6: Toshkent shahar BXM
A7: TBATM011 | B7: 44650 | C7: 0 | D7: 44650 | E7: 4509650 | F7: 0 | G7: 4509650 | H7: 4465000 | I7: 0 | J7: 4465000 | K7: 11279 | L7: Қарши БХМ
A8: TBATM043 | B8: 2000 | C8: 0 | D8: 2000 | E8: 202000 | F8: 0 | G8: 202000 | H8: 200000 | I8: 0 | J8: 200000 | K8: 10725 | L8: Toshkent shahar BXM
